Workbook

Sheet Data Barang
C2: sept
A3: No | B3: Nama Barang | C3: Stok Awal | D3: Satuan
A4: 1 | B4: Penggaris Butterfly 30 cm | C4: 2 | D4: Pcs
A5: 2 | B5: Lakban Coklat Besar 2 inch (lebar 48mm x 90 yard) | C5: 3 | D5: Pcs
A6: 3 | B6: Lakban Hitam Besar 2 inch (lebar 48mm x 90 yard) | C6: 5 | D6: Pcs
A7: 4 | B7: Lakban Bening 2 inch (lebar 48mm x 90 yard) | C7: 2 | D7: Pcs
A8: 5 | B8: Lakban Bening Daimaru Sedang | C8: 6 | D8: Pcs
A9: 6 | B9: Lakban Bening Ukuran Kecil | C9: 7 | D9: Pcs
A10: 7 | B10: Double Tip Ukuran Sedang | C10: 3 | D10: Pcs
A11: 8 | B11: Double Tim 3M | C11: 1 | D11: Pcs
A12: 9 | B12: Label T & J No. 99 1 pack isi 10 pcs | C12: 30 | D12: Pcs
A13: 10 | B13: Label T & J No. 103 1 pack isi 10 pcs | C13: 20 | D13: Pcs
A14: 11 | B14: Label T & J No. 104 1 pack isi 10 pcs | C14: 60 | D14: Pcs
A15: 12 | B15: Label T & J No. 109 1 pack isi 10 pcs | C15: 30 | D15: Pcs
... A39: 36 | B39: Bindex File Jumbo 1034B | C39: 7 | D39: Pcs
A40: 37 | B40: Snowman Spidol Permanent Black 1 pack isi 12 | C40: 67 | D40: Pcs | E40: .
A41: 38 | B41: Snowman Spidol Papan Tulis BG-12 Black | C41: 12 | D41: Pcs
A42: 39 | B42: Snowman Spidol Papan Tulis BG-12 Blue | C42: 4 | D42: Pcs
A43: 40 | B43: Snowman Spidol Papan Tulis BG-12 Red | C43: 6 | D43: Pcs
A44: 41 | B44: Snowman Spidol ABG - 12 Black | C44: 11 | D44: Pcs
A45: 42 | B45: Spidol Besar Snowman 500 | C45: 1 | D45: Pcs
A46: 43 | B46: Spidol Snowman 450 | C46: 1 | D46: Pcs
A47: 44 | B47: Refill Snowman V5 0.7 1 pack isi 12 pcs | C47: 20 | D47: Pcs
A48: 45 | B48: Stabilo Plan 2,5 - 3,5 MM Red | C48: 1 | D48: Pcs
A49: 46 | B49: Gunting Scissors Joyko SC-828 | C49: 0 | D49: Pcs
A50: 47 | B50: Gunting Scissors Joyko SC-838 | C50: 5 | D50: Pcs
A51: 48 | B51: Gunting Scissors Joyko SC-848 | C51: 2 | D51: Pcs
A52: 49 | B52: Set Pen Holder Tempat Alat Tulis Joyko Meja Kantor DS-23 | C52: 1 | D52: Pcs
... A55: 52 | B55: Rak Dokumen Ukuran Kertas F4 (2 susun) | C55: 3 | D55: Pcs
A56: 53 | B56: Materai 10000 (1 Lembar isi 100 Pcs) | C56: - | D56: Pcs
A57: 54 | B57: Stapler Kenko HD-10N | C57: 0 | D57: Pcs
A58: 55 | B58: Stapler Kenko HD-50N | C58: 8 | D58: Pcs
A59: 56 | B59: Isi Staples No.3 - 1 M Fine 1 pack isi 20 box kecil | C59: 40 | D59: Box Kecil
A60: 57 | B60: Isi Staples Kenko No.3-1M 1 pack isi 20 box kecil | C60: 60 | D60: Pcs
A61: 58 | B61: Isi Staples Kenko No.10-1M 1 pack isi 20 box kecil | C61: 40 | D61: Pcs
A62: 59 | B62: Etona Staples No.10 - 1 M | C62: 1 | D62: Pack
A63: 60 | B63: Alat Pelepas Staples SR 51 | C63: 4 | D63: Pcs
A64: 61 | B64: Cutter Joyko L-500 | C64: 2 | D64: Pcs
A65: 62 | B65: Cutter Joyko A-300 | C65: 4 | D65: Pcs
A66: 63 | B66: Isi Cutter Joyko L-500 1 pack isi 12 pcs | C66: 36 | D66: Pcs
...

Sheet Barang Masuk
A1: Pengadaan Barang
A3: No | B3: Tanggal Masuk | C3: Nama Barang | D3: Jumlah
A4: =ROW()-3 -> 1 | B4: 46048 | C4: Lakban Hitam Besar 2 inch (lebar 48mm x 90 yard) | D4: 10
A5: =ROW()-3 -> 2 | B5: 46048 | C5: Lakban Bening 2 inch (lebar 48mm x 90 yard) | D5: 10
A6: =ROW()-3 -> 3 | B6: 46048 | C6: Lakban Bening Daimaru Sedang | D6: 10
A7: =ROW()-3 -> 4 | B7: 46048 | C7: Lakban Bening Ukuran Kecil | D7: 10
A8: =ROW()-3 -> 5 | B8: 46048 | C8: Double Tip Ukuran Sedang | D8: 5
A9: =ROW()-3 -> 6 | B9: 46048 | C9: Double Tim 3M | D9: 10
A10: =ROW()-3 -> 7 | B10: 46048 | C10: Label T & J No. 99 1 pack isi 10 pcs | D10: 10
A11: =ROW()-3 -> 8 | B11: 46048 | C11: Label T & J No. 103 1 pack isi 10 pcs | D11: 10
A12: =ROW()-3 -> 9 | B12: 46048 | C12: Label T & J No. 109 1 pack isi 10 pcs | D12: 20
A13: =ROW()-3 -> 10 | B13: 46048 | C13: Label T & J No. 126 1 pack isi 10 pcs | D13: 20
A14: =ROW()-3 -> 11 | B14: 46048 | C14: Ballpoint Pilot Ball Liner Medium Black 1 pack isi 12 pcs | D14: 12
A15: =ROW()-3 -> 12 | B15: 46048 | C15: Clear Holder Folio F4 Size Isi 60 | D15: 60
... A43: =ROW()-3 -> 40 | B43: 46142 | C43: Amplop Putih Jendela BPJS (1 Pack isi 100 Pcs) | D43: 60
A44: =ROW()-3 -> 41
A45: =ROW()-3 -> 42
A46: =ROW()-3 -> 43
A47: =ROW()-3 -> 44
A48: =ROW()-3 -> 45
A49: =ROW()-3 -> 46
A50: =ROW()-3 -> 47
A51: =ROW()-3 -> 48
A52: =ROW()-3 -> 49
A53: =ROW()-3 -> 50
A54: =ROW()-3 -> 51
A55: =ROW()-3 -> 52
... A1049: =ROW()-3 -> 1046

Sheet Barang Keluar
A1: Barang Keluar
A4: No | B4: Tanggal Keluar | C4: Nama Barang | D4: Jumlah | E4: Permintaan
A5: =ROW()-4 -> 1 | B5: 46028 | C5: Kertas A4 (75 gram) | D5: 2 | E5: SDMUK
A6: =ROW()-4 -> 2 | B6: 46028 | C6: Kertas A4 (75 gram) | D6: 2 | E6: PKP
A7: =ROW()-4 -> 3 | B7: 46030 | C7: Kertas A4 (75 gram) | D7: 3 | E7: Yanser
A8: =ROW()-4 -> 4 | B8: 46032 | C8: Kertas A4 (75 gram) | D8: 2 | E8: Kepser
A9: =ROW()-4 -> 5 | B9: 46033 | C9: Kertas A4 (75 gram) | D9: 2 | E9: Yanfaskes
A10: =ROW()-4 -> 6 | B10: 46033 | C10: Kertas A4 (75 gram) | D10: 2 | E10: PMU
A11: =ROW()-4 -> 7 | B11: 46048 | C11: Kertas A4 (75 gram) | D11: 2 | E11: Kepser
A12: =ROW()-4 -> 8 | B12: 46056 | C12: Double Sided Tape Perekat (12mm x 13M) | D12: 1 | E12: Adit OB
A13: =ROW()-4 -> 9 | B13: 46057 | C13: Baterai Alkalin 1.5V A2 Isi 6 | D13: 6 | E13: Mba Rieza
A14: =ROW()-4 -> 10 | B14: 46065 | C14: Kenko Glue Stick 25 g 1 pack isi 12 pcs | D14: 2 | E14: Sina
A15: =ROW()-4 -> 11 | B15: 46065 | C15: Baterai Alkalin 1.5V A2 Isi 6 | D15: 4 | E15: Sina
A16: =ROW()-4 -> 12 | B16: 46071 | C16: Isi Staples Kenko No.10-1M 1 pack isi 20 box kecil | D16: 2 | E16: Sina
... A57: =ROW()-4 -> 53 | B57: 46120 | C57: Highlighter-Kuning (Stabilo Boss Original - Hijau Muda) | D57: 1 | E57: Mas Made
A58: =ROW()-4 -> 54 | B58: 46120 | E58: Mas Made
A59: =ROW()-4 -> 55 | B59: 46120 | C59: Sign Here Biasa Joyko 1 pack isi 24 pcs | D59: 10 | E59: Mas Made
A60: =ROW()-4 -> 56 | B60: 46120 | C60: Kertas A4 (75 gram) | D60: 1 | E60: Mba dian
A61: =ROW()-4 -> 57 | B61: 46120 | C61: Kertas A4 (75 gram) | D61: 1 | E61: Mba Gea
A62: =ROW()-4 -> 58 | B62: 46125 | C62: Amplop Coklat BPJS Kesehatan 1 pack isi 10 pcs | D62: 100 | E62: Yanfaskes
A63: =ROW()-4 -> 59 | B63: 46125 | C63: Kertas A4 (75 gram) | D63: 2 | E63: Kepser
A64: =ROW()-4 -> 60 | B64: 46125 | C64: Binder Clips Joyko No. 155 1 dus isi 12 box kecil | D64: 2 | E64: Mas iyan
A65: =ROW()-4 -> 61 | B65: 46125 | C65: Binder Clips Joyko No. 111 1 dus isi 12 box kecil | D65: 2 | E65: Mas iyan
A66: =ROW()-4 -> 62 | B66: 46125 | C66: Binder Clips Joyko No. 107 1 dus isi 12 box kecil | D66: 2 | E66: Mas iyan
A67: =ROW()-4 -> 63 | B67: 46125 | C67: Paper Clips No. 3 1 pack isi 10 box kecil | D67: 3 | E67: Mas iyan
A68: =ROW()-4 -> 64 | B68: 46129 | C68: Kertas A4 (75 gram) | D68: 2 | E68: sdmuk
A69: =ROW()-4 -> 65 | B69: 46129 | C69: Kertas A4 (75 gram) | D69: 2 | E69: PKP
A70: =ROW()-4 -> 66 | B70: 46132 | C70: Kertas A4 (75 gram) | D70: 5 | E70: Yanser
... A83: =ROW()-4 -> 79 | B83: 46146 | C83: Amplop Putih Jendela BPJS (1 Dus isi 100 Pcs) | D83: 8 | E83: PKP
A84: =ROW()-4 -> 80 | B84: 46289 | C84: Penggaris Butterfly 30 cm | D84: 10
A85: =ROW()-4 -> 81
A86: =ROW()-4 -> 82
A87: =ROW()-4 -> 83
A88: =ROW()-4 -> 84
A89: =ROW()-4 -> 85
A90: =ROW()-4 -> 86
A91: =ROW()-4 -> 87
A92: =ROW()-4 -> 88
A93: =ROW()-4 -> 89
A94: =ROW()-4 -> 90
...

Sheet Sisa Stok Barang
A1: Sisa Stok Barang
C3: Bulan | D3: Oktober | H3: awal bulan | I3: akhir bulan
C4: Tahun | D4: 2026 | H4: =DATE($D$4,MATCH($D$3,Bantu!$C$3:$C$14,),1) -> 46296 | I4: =EDATE(H4,1)-1 -> 46326
A6: No | B6: Nama Barang | C6: Satuan | D6: Stok Awal | E6: Jumlah Masuk | F6: Jumlah Keluar | G6: Sisa Stok
A7: =ROW()-6 -> 1 | B7: Penggaris Butterfly 30 cm | C7: Pcs | D7: =SUMIFS(Table1[Stok Awal],Table1[Nama Barang],Table4[[#This Row],[Nama Barang]])+ SUMIFS(Table2[Jumlah],Table2[Nama Barang],Table4[[#This Row],[Nama Barang]],Table2[Tanggal Masuk],"<"&'Sisa Stok Barang'!$H$4)- SUMIFS(Table3[Jumlah],Table3[Nama Barang],Table4[[#This Row],[Nama Barang]],Table3[Tanggal Keluar],"<"&'Sisa Stok Barang'!$H$4) -> -9 | E7: =SUMIFS(Table2[Jumlah],Table2[Nama Barang],Table4[[#This Row],[Nama Barang]],Table2[Tanggal Masuk],">="&'Sisa Stok Barang'!$H$4,Table2[Tanggal Masuk],"<="&'Sisa Stok Barang'!$I$4) -> 0 | F7: =SUMIFS(Table3[Jumlah],Table3[Nama Barang],Table4[[#This Row],[Nama Barang]],Table3[Tanggal Keluar],">="&'Sisa Stok Barang'!$H$4,Table3[Tanggal Keluar],"<="&'Sisa Stok Barang'!$I$4) -> 0 | G7: =Table4[[#This Row],[Stok Awal]]+Table4[[#This Row],[Jumlah Masuk]]-Table4[[#This Row],[Jumlah Keluar]] -> -9
A8: =ROW()-6 -> 2 | B8: Lakban Coklat Besar 2 inch (lebar 48mm x 90 yard) | C8: Pcs | D8: =SUMIFS(Table1[Stok Awal],Table1[Nama Barang],Table4[[#This Row],[Nama Barang]])+ SUMIFS(Table2[Jumlah],Table2[Nama Barang],Table4[[#This Row],[Nama Barang]],Table2[Tanggal Masuk],"<"&'Sisa Stok Barang'!$H$4)- SUMIFS(Table3[Jumlah],Table3[Nama Barang],Table4[[#This Row],[Nama Barang]],Table3[Tanggal Keluar],"<"&'Sisa Stok Barang'!$H$4) -> 3 | E8: =SUMIFS(Table2[Jumlah],Table2[Nama Barang],Table4[[#This Row],[Nama Barang]],Table2[Tanggal Masuk],">="&'Sisa Stok Barang'!$H$4,Table2[Tanggal Masuk],"<="&'Sisa Stok Barang'!$I$4) -> 0 | F8: =SUMIFS(Table3[Jumlah],Table3[Nama Barang],Table4[[#This Row],[Nama Barang]],Table3[Tanggal Keluar],">="&'Sisa Stok Barang'!$H$4,Table3[Tanggal Keluar],"<="&'Sisa Stok Barang'!$I$4) -> 0 | G8: =Table4[[#This Row],[Stok Awal]]+Table4[[#This Row],[Jumlah Masuk]]-Table4[[#This Row],[Jumlah Keluar]] -> 3
A9: =ROW()-6 -> 3 | B9: Lakban Hitam Besar 2 inch (lebar 48mm x 90 yard) | C9: Pcs | D9: =SUMIFS(Table1[Stok Awal],Table1[Nama Barang],Table4[[#This Row],[Nama Barang]])+ SUMIFS(Table2[Jumlah],Table2[Nama Barang],Table4[[#This Row],[Nama Barang]],Table2[Tanggal Masuk],"<"&'Sisa Stok Barang'!$H$4)- SUMIFS(Table3[Jumlah],Table3[Nama Barang],Table4[[#This Row],[Nama Barang]],Table3[Tanggal Keluar],"<"&'Sisa Stok Barang'!$H$4) -> 15 | E9: =SUMIFS(Table2[Jumlah],Table2[Nama Barang],Table4[[#This Row],[Nama Barang]],Table2[Tanggal Masuk],">="&'Sisa Stok Barang'!$H$4,Table2[Tanggal Masuk],"<="&'Sisa Stok Barang'!$I$4) -> 0 | F9: =SUMIFS(Table3[Jumlah],Table3[Nama Barang],Table4[[#This Row],[Nama Barang]],Table3[Tanggal Keluar],">="&'Sisa Stok Barang'!$H$4,Table3[Tanggal Keluar],"<="&'Sisa Stok Barang'!$I$4) -> 0 | G9: =Table4[[#This Row],[Stok Awal]]+Table4[[#This Row],[Jumlah Masuk]]-Table4[[#This Row],[Jumlah Keluar]] -> 15
A10: =ROW()-6 -> 4 | B10: Lakban Bening 2 inch (lebar 48mm x 90 yard) | C10: Pcs | D10: =SUMIFS(Table1[Stok Awal],Table1[Nama Barang],Table4[[#This Row],[Nama Barang]])+ SUMIFS(Table2[Jumlah],Table2[Nama Barang],Table4[[#This Row],[Nama Barang]],Table2[Tanggal Masuk],"<"&'Sisa Stok Barang'!$H$4)- SUMIFS(Table3[Jumlah],Table3[Nama Barang],Table4[[#This Row],[Nama Barang]],Table3[Tanggal Keluar],"<"&'Sisa Stok Barang'!$H$4) -> 11 | E10: =SUMIFS(Table2[Jumlah],Table2[Nama Barang],Table4[[#This Row],[Nama Barang]],Table2[Tanggal Masuk],">="&'Sisa Stok Barang'!$H$4,Table2[Tanggal Masuk],"<="&'Sisa Stok Barang'!$I$4) -> 0 | F10: =SUMIFS(Table3[Jumlah],Table3[Nama Barang],Table4[[#This Row],[Nama Barang]],Table3[Tanggal Keluar],">="&'Sisa Stok Barang'!$H$4,Table3[Tanggal Keluar],"<="&'Sisa Stok Barang'!$I$4) -> 0 | G10: =Table4[[#This Row],[Stok Awal]]+Table4[[#This Row],[Jumlah Masuk]]-Table4[[#This Row],[Jumlah Keluar]] -> 11
A11: =ROW()-6 -> 5 | B11: Lakban Bening Daimaru Sedang | C11: Pcs | D11: =SUMIFS(Table1[Stok Awal],Table1[Nama Barang],Table4[[#This Row],[Nama Barang]])+ SUMIFS(Table2[Jumlah],Table2[Nama Barang],Table4[[#This Row],[Nama Barang]],Table2[Tanggal Masuk],"<"&'Sisa Stok Barang'!$H$4)- SUMIFS(Table3[Jumlah],Table3[Nama Barang],Table4[[#This Row],[Nama Barang]],Table3[Tanggal Keluar],"<"&'Sisa Stok Barang'!$H$4) -> 15 | E11: =SUMIFS(Table2[Jumlah],Table2[Nama Barang],Table4[[#This Row],[Nama Barang]],Table2[Tanggal Masuk],">="&'Sisa Stok Barang'!$H$4,Table2[Tanggal Masuk],"<="&'Sisa Stok Barang'!$I$4) -> 0 | F11: =SUMIFS(Table3[Jumlah],Table3[Nama Barang],Table4[[#This Row],[Nama Barang]],Table3[Tanggal Keluar],">="&'Sisa Stok Barang'!$H$4,Table3[Tanggal Keluar],"<="&'Sisa Stok Barang'!$I$4) -> 0 | G11: =Table4[[#This Row],[Stok Awal]]+Table4[[#This Row],[Jumlah Masuk]]-Table4[[#This Row],[Jumlah Keluar]] -> 15
A12: =ROW()-6 -> 6 | B12: Lakban Bening Ukuran Kecil | C12: Pcs | D12: =SUMIFS(Table1[Stok Awal],Table1[Nama Barang],Table4[[#This Row],[Nama Barang]])+ SUMIFS(Table2[Jumlah],Table2[Nama Barang],Table4[[#This Row],[Nama Barang]],Table2[Tanggal Masuk],"<"&'Sisa Stok Barang'!$H$4)- SUMIFS(Table3[Jumlah],Table3[Nama Barang],Table4[[#This Row],[Nama Barang]],Table3[Tanggal Keluar],"<"&'Sisa Stok Barang'!$H$4) -> 17 | E12: =SUMIFS(Table2[Jumlah],Table2[Nama Barang],Table4[[#This Row],[Nama Barang]],Table2[Tanggal Masuk],">="&'Sisa Stok Barang'!$H$4,Table2[Tanggal Masuk],"<="&'Sisa Stok Barang'!$I$4) -> 0 | F12: =SUMIFS(Table3[Jumlah],Table3[Nama Barang],Table4[[#This Row],[Nama Barang]],Table3[Tanggal Keluar],">="&'Sisa Stok Barang'!$H$4,Table3[Tanggal Keluar],"<="&'Sisa Stok Barang'!$I$4) -> 0 | G12: =Table4[[#This Row],[Stok Awal]]+Table4[[#This Row],[Jumlah Masuk]]-Table4[[#This Row],[Jumlah Keluar]] -> 17
A13: =ROW()-6 -> 7 | B13: Double Tip Ukuran Sedang | C13: Pcs | D13: =SUMIFS(Table1[Stok Awal],Table1[Nama Barang],Table4[[#This Row],[Nama Barang]])+ SUMIFS(Table2[Jumlah],Table2[Nama Barang],Table4[[#This Row],[Nama Barang]],Table2[Tanggal Masuk],"<"&'Sisa Stok Barang'!$H$4)- SUMIFS(Table3[Jumlah],Table3[Nama Barang],Table4[[#This Row],[Nama Barang]],Table3[Tanggal Keluar],"<"&'Sisa Stok Barang'!$H$4) -> 8 | E13: =SUMIFS(Table2[Jumlah],Table2[Nama Barang],Table4[[#This Row],[Nama Barang]],Table2[Tanggal Masuk],">="&'Sisa Stok Barang'!$H$4,Table2[Tanggal Masuk],"<="&'Sisa Stok Barang'!$I$4) -> 0 | F13: =SUMIFS(Table3[Jumlah],Table3[Nama Barang],Table4[[#This Row],[Nama Barang]],Table3[Tanggal Keluar],">="&'Sisa Stok Barang'!$H$4,Table3[Tanggal Keluar],"<="&'Sisa Stok Barang'!$I$4) -> 0 | G13: =Table4[[#This Row],[Stok Awal]]+Table4[[#This Row],[Jumlah Masuk]]-Table4[[#This Row],[Jumlah Keluar]] -> 8
A14: =ROW()-6 -> 8 | B14: Double Tim 3M | C14: Pcs | D14: =SUMIFS(Table1[Stok Awal],Table1[Nama Barang],Table4[[#This Row],[Nama Barang]])+ SUMIFS(Table2[Jumlah],Table2[Nama Barang],Table4[[#This Row],[Nama Barang]],Table2[Tanggal Masuk],"<"&'Sisa Stok Barang'!$H$4)- SUMIFS(Table3[Jumlah],Table3[Nama Barang],Table4[[#This Row],[Nama Barang]],Table3[Tanggal Keluar],"<"&'Sisa Stok Barang'!$H$4) -> 10 | E14: =SUMIFS(Table2[Jumlah],Table2[Nama Barang],Table4[[#This Row],[Nama Barang]],Table2[Tanggal Masuk],">="&'Sisa Stok Barang'!$H$4,Table2[Tanggal Masuk],"<="&'Sisa Stok Barang'!$I$4) -> 0 | F14: =SUMIFS(Table3[Jumlah],Table3[Nama Barang],Table4[[#This Row],[Nama Barang]],Table3[Tanggal Keluar],">="&'Sisa Stok Barang'!$H$4,Table3[Tanggal Keluar],"<="&'Sisa Stok Barang'!$I$4) -> 0 | G14: =Table4[[#This Row],[Stok Awal]]+Table4[[#This Row],[Jumlah Masuk]]-Table4[[#This Row],[Jumlah Keluar]] -> 10
A15: =ROW()-6 -> 9 | B15: Label T & J No. 99 1 pack isi 10 pcs | C15: Pcs | D15: =SUMIFS(Table1[Stok Awal],Table1[Nama Barang],Table4[[#This Row],[Nama Barang]])+ SUMIFS(Table2[Jumlah],Table2[Nama Barang],Table4[[#This Row],[Nama Barang]],Table2[Tanggal Masuk],"<"&'Sisa Stok Barang'!$H$4)- SUMIFS(Table3[Jumlah],Table3[Nama Barang],Table4[[#This Row],[Nama Barang]],Table3[Tanggal Keluar],"<"&'Sisa Stok Barang'!$H$4) -> 40 | E15: =SUMIFS(Table2[Jumlah],Table2[Nama Barang],Table4[[#This Row],[Nama Barang]],Table2[Tanggal Masuk],">="&'Sisa Stok Barang'!$H$4,Table2[Tanggal Masuk],"<="&'Sisa Stok Barang'!$I$4) -> 0 | F15: =SUMIFS(Table3[Jumlah],Table3[Nama Barang],Table4[[#This Row],[Nama Barang]],Table3[Tanggal Keluar],">="&'Sisa Stok Barang'!$H$4,Table3[Tanggal Keluar],"<="&'Sisa Stok Barang'!$I$4) -> 0 | G15: =Table4[[#This Row],[Stok Awal]]+Table4[[#This Row],[Jumlah Masuk]]-Table4[[#This Row],[Jumlah Keluar]] -> 40
A16: =ROW()-6 -> 10 | B16: Label T & J No. 103 1 pack isi 10 pcs | C16: Pcs | D16: =SUMIFS(Table1[Stok Awal],Table1[Nama Barang],Table4[[#This Row],[Nama Barang]])+ SUMIFS(Table2[Jumlah],Table2[Nama Barang],Table4[[#This Row],[Nama Barang]],Table2[Tanggal Masuk],"<"&'Sisa Stok Barang'!$H$4)- SUMIFS(Table3[Jumlah],Table3[Nama Barang],Table4[[#This Row],[Nama Barang]],Table3[Tanggal Keluar],"<"&'Sisa Stok Barang'!$H$4) -> 30 | E16: =SUMIFS(Table2[Jumlah],Table2[Nama Barang],Table4[[#This Row],[Nama Barang]],Table2[Tanggal Masuk],">="&'Sisa Stok Barang'!$H$4,Table2[Tanggal Masuk],"<="&'Sisa Stok Barang'!$I$4) -> 0 | F16: =SUMIFS(Table3[Jumlah],Table3[Nama Barang],Table4[[#This Row],[Nama Barang]],Table3[Tanggal Keluar],">="&'Sisa Stok Barang'!$H$4,Table3[Tanggal Keluar],"<="&'Sisa Stok Barang'!$I$4) -> 0 | G16: =Table4[[#This Row],[Stok Awal]]+Table4[[#This Row],[Jumlah Masuk]]-Table4[[#This Row],[Jumlah Keluar]] -> 30
A17: =ROW()-6 -> 11 | B17: Label T & J No. 104 1 pack isi 10 pcs | C17: Pcs | D17: =SUMIFS(Table1[Stok Awal],Table1[Nama Barang],Table4[[#This Row],[Nama Barang]])+ SUMIFS(Table2[Jumlah],Table2[Nama Barang],Table4[[#This Row],[Nama Barang]],Table2[Tanggal Masuk],"<"&'Sisa Stok Barang'!$H$4)- SUMIFS(Table3[Jumlah],Table3[Nama Barang],Table4[[#This Row],[Nama Barang]],Table3[Tanggal Keluar],"<"&'Sisa Stok Barang'!$H$4) -> 60 | E17: =SUMIFS(Table2[Jumlah],Table2[Nama Barang],Table4[[#This Row],[Nama Barang]],Table2[Tanggal Masuk],">="&'Sisa Stok Barang'!$H$4,Table2[Tanggal Masuk],"<="&'Sisa Stok Barang'!$I$4) -> 0 | F17: =SUMIFS(Table3[Jumlah],Table3[Nama Barang],Table4[[#This Row],[Nama Barang]],Table3[Tanggal Keluar],">="&'Sisa Stok Barang'!$H$4,Table3[Tanggal Keluar],"<="&'Sisa Stok Barang'!$I$4) -> 0 | G17: =Table4[[#This Row],[Stok Awal]]+Table4[[#This Row],[Jumlah Masuk]]-Table4[[#This Row],[Jumlah Keluar]] -> 60
A18: =ROW()-6 -> 12 | B18: Label T & J No. 109 1 pack isi 10 pcs | C18: Pcs | D18: =SUMIFS(Table1[Stok Awal],Table1[Nama Barang],Table4[[#This Row],[Nama Barang]])+ SUMIFS(Table2[Jumlah],Table2[Nama Barang],Table4[[#This Row],[Nama Barang]],Table2[Tanggal Masuk],"<"&'Sisa Stok Barang'!$H$4)- SUMIFS(Table3[Jumlah],Table3[Nama Barang],Table4[[#This Row],[Nama Barang]],Table3[Tanggal Keluar],"<"&'Sisa Stok Barang'!$H$4) -> 50 | E18: =SUMIFS(Table2[Jumlah],Table2[Nama Barang],Table4[[#This Row],[Nama Barang]],Table2[Tanggal Masuk],">="&'Sisa Stok Barang'!$H$4,Table2[Tanggal Masuk],"<="&'Sisa Stok Barang'!$I$4) -> 0 | F18: =SUMIFS(Table3[Jumlah],Table3[Nama Barang],Table4[[#This Row],[Nama Barang]],Table3[Tanggal Keluar],">="&'Sisa Stok Barang'!$H$4,Table3[Tanggal Keluar],"<="&'Sisa Stok Barang'!$I$4) -> 0 | G18: =Table4[[#This Row],[Stok Awal]]+Table4[[#This Row],[Jumlah Masuk]]-Table4[[#This Row],[Jumlah Keluar]] -> 50
... A178: =ROW()-6 -> 172 | B178: Kertas Coklat Lembaran (90x120) | C178: Pcs | D178: =SUMIFS(Table1[Stok Awal],Table1[Nama Barang],Table4[[#This Row],[Nama Barang]])+ SUMIFS(Table2[Jumlah],Table2[Nama Barang],Table4[[#This Row],[Nama Barang]],Table2[Tanggal Masuk],"<"&'Sisa Stok Barang'!$H$4)- SUMIFS(Table3[Jumlah],Table3[Nama Barang],Table4[[#This Row],[Nama Barang]],Table3[Tanggal Keluar],"<"&'Sisa Stok Barang'!$H$4) -> 5 | E178: =SUMIFS(Table2[Jumlah],Table2[Nama Barang],Table4[[#This Row],[Nama Barang]],Table2[Tanggal Masuk],">="&'Sisa Stok Barang'!$H$4,Table2[Tanggal Masuk],"<="&'Sisa Stok Barang'!$I$4) -> 0 | F178: =SUMIFS(Table3[Jumlah],Table3[Nama Barang],Table4[[#This Row],[Nama Barang]],Table3[Tanggal Keluar],">="&'Sisa Stok Barang'!$H$4,Table3[Tanggal Keluar],"<="&'Sisa Stok Barang'!$I$4) -> 0 | G178: =Table4[[#This Row],[Stok Awal]]+Table4[[#This Row],[Jumlah Masuk]]-Table4[[#This Row],[Jumlah Keluar]] -> 5

Sheet Bantu
C3: Januari | G3: {=_xlfn.UNIQUE(Table4[Nama Barang])} -> Penggaris Butterfly 30 cm
C4: Februari | G4: Lakban Coklat Besar 2 inch (lebar 48mm x 90 yard)
C5: Maret | G5: Lakban Hitam Besar 2 inch (lebar 48mm x 90 yard)
C6: April | G6: Lakban Bening 2 inch (lebar 48mm x 90 yard)
C7: Mei | G7: Lakban Bening Daimaru Sedang
C8: Juni | G8: Lakban Bening Ukuran Kecil
C9: Juli | G9: Double Tip Ukuran Sedang
C10: Agustus | G10: Double Tim 3M
C11: September | G11: Label T & J No. 99 1 pack isi 10 pcs
C12: Oktober | G12: Label T & J No. 103 1 pack isi 10 pcs
C13: November | G13: Label T & J No. 104 1 pack isi 10 pcs
C14: Desember | G14: Label T & J No. 109 1 pack isi 10 pcs
G15: Label T & J No. 112 1 pack isi 10 pcs
G16: Label T & J No. 121 1 pack isi 10 pcs
G17: Label T & J No. 123 1 pack isi 10 pcs
G18: Label T & J No. 124 1 pack isi 10 pcs
G19: Label T & J No. 126 1 pack isi 10 pcs
G20: Baterai Alkalin 1.5V A2 Isi 6
G21: Baterai Alkalin 1.5V A3 Isi 6
G22: Ballpoint Pilot Ball Liner Medium Black 1 pack isi 12 pcs
G23: Ballpoint Pilot Ball Liner Medium Blue 1 pack isi 12 pcs
G24: Ballpoint Zebra Sarasa Clip Black (1.0) 1 pack isi 12 pcs
G25: Ballpoint Zebra Sarasa Clip Black (0,7) 1 pack isi 12 pcs
G26: Ballpoint Zebra Sarasa Clip Black (0.5) 1 pack isi 12 pcs
... G173: Kertas Coklat Lembaran (90x120)

Sheet ATK 1 tahun 
A1: STOK OPNAME ALAT TULIS KANTOR TAHUN 2025
A2: BPJS KESEHATAN CABANG JAKARTA UTARA
C4: Februari 2025 | I4: Mei 2025 | O4: Juli | U4: September | AA4: November | AG4: Januari 2026
A5: NO | B5: URAIAN | C5: SATUAN | D5: STOK AWAL | E5: Sisa Stok | F5: Pengadaan | G5: Total Setelah Pengadan | H5: Jumlah Realisasi | I5: SATUAN | J5: STOK AWAL | K5: Sisa Stok | L5: Pengadaan | M5: Total Setelah Pengadan | N5: Jumlah Realisasi | O5: SATUAN | P5: STOK AWAL | Q5: Sisa Stok | R5: Pengadaan | S5: Total Setelah Pengadan | T5: Jumlah Realisasi | U5: SATUAN | V5: STOK AWAL | W5: Sisa Stok | X5: Pengadaan | Y5: Total Setelah Pengadan | Z5: Jumlah Realisasi | AA5: SATUAN | AB5: STOK AWAL | AC5: Sisa Stok | AD5: Pengadaan | AE5: Total Setelah Pengadan | AF5: Jumlah Realisasi | AG5: SATUAN | AH5: STOK AWAL | AI5: Sisa Stok | AJ5: Pengadaan | AK5: Total Setelah Pengadan | AL5: Jumlah Realisasi | AM5: Stok diambil Februari
A6: 1 | B6: Penggaris Butterfly 30 cm | C6: Pcs | D6: 4 | E6: 4 | G6: 4 | I6: Pcs | J6: 4 | K6: 1 | L6: 3 | M6: =L6+K6 -> 4 | N6: 22500 | O6: Pcs | P6: 4 | Q6: 2 | S6: =R6+Q6 -> 2 | U6: Pcs | V6: =S6 -> 2 | W6: 2 | Y6: =X6+W6 -> 2 | AA6: Pcs | AB6: =Y6 -> 2 | AC6: 2 | AD6: 5 | AE6: =AD6+AC6 -> 7 | AF6: 30000 | AG6: Pcs | AH6: =AE6 -> 7 | AI6: 7 | AK6: =AJ6+AI6 -> 7
A7: 2 | B7: Lakban Coklat Besar 2 inch (lebar 48mm x 90 yard) | C7: Pcs | D7: 8 | E7: 7 | G7: 7 | I7: Pcs | J7: 7 | K7: 7 | M7: =L7+K7 -> 7 | O7: Pcs | P7: 7 | Q7: 7 | S7: =R7+Q7 -> 7 | U7: Pcs | V7: =S7 -> 7 | W7: 7 | Y7: =X7+W7 -> 7 | AA7: Pcs | AB7: =Y7 -> 7 | AC7: 7 | AE7: =AD7+AC7 -> 7 | AG7: Pcs | AH7: =AE7 -> 7 | AI7: 7 | AK7: =AJ7+AI7 -> 7
A8: 3 | B8: Lakban Hitam Besar 2 inch (lebar 48mm x 90 yard) | C8: Pcs | D8: 5 | E8: 1 | F8: 5 | G8: 6 | H8: 80000 | I8: Pcs | J8: 6 | K8: 4 | M8: =L8+K8 -> 4 | O8: Pcs | P8: 4 | Q8: 2 | S8: =R8+Q8 -> 2 | U8: Pcs | V8: =S8 -> 2 | W8: 1 | Y8: =X8+W8 -> 1 | AA8: Pcs | AB8: =Y8 -> 1 | AC8: 1 | AE8: =AD8+AC8 -> 1 | AG8: Pcs | AH8: =AE8 -> 1 | AI8: 0 | AJ8: 10 | AK8: =AJ8+AI8 -> 10
A9: 4 | B9: Lakban Bening 2 inch (lebar 48mm x 90 yard) | C9: Pcs | D9: 3 | E9: 0 | F9: 3 | G9: 3 | H9: 28500 | I9: Pcs | J9: 3 | K9: 1 | L9: 5 | M9: =L9+K9 -> 6 | N9: 47500 | O9: Pcs | P9: 6 | Q9: 4 | S9: =R9+Q9 -> 4 | U9: Pcs | V9: =S9 -> 4 | W9: 2 | X9: 3 | Y9: =X9+W9 -> 5 | Z9: 36000 | AA9: Pcs | AB9: =Y9 -> 5 | AC9: 3 | AE9: =AD9+AC9 -> 3 | AG9: Pcs | AH9: =AE9 -> 3 | AI9: 0 | AJ9: 10 | AK9: =AJ9+AI9 -> 10 | AM9: 2
A10: 5 | B10: Lakban Bening Daimaru Sedang | C10: Pcs | D10: 5 | E10: 0 | F10: 5 | G10: 5 | H10: 37500 | I10: Pcs | J10: 5 | K10: 1 | L10: 5 | M10: =L10+K10 -> 6 | N10: 37500 | O10: Pcs | P10: 6 | Q10: 3 | S10: =R10+Q10 -> 3 | U10: Pcs | V10: =S10 -> 3 | W10: 1 | X10: 3 | Y10: =X10+W10 -> 4 | Z10: 24000 | AA10: Pcs | AB10: =Y10 -> 4 | AC10: 3 | AE10: =AD10+AC10 -> 3 | AG10: Pcs | AH10: =AE10 -> 3 | AI10: 2 | AJ10: 10 | AK10: =AJ10+AI10 -> 12
A11: 6 | B11: Lakban Bening Ukuran Kecil | C11: Pcs | D11: 2 | E11: 2 | G11: 2 | I11: Pcs | J11: 2 | K11: 0 | L11: 5 | M11: =L11+K11 -> 5 | N11: 17500 | O11: Pcs | P11: 5 | Q11: 3 | S11: =R11+Q11 -> 3 | U11: Pcs | V11: =S11 -> 3 | W11: 1 | X11: 3 | Y11: =X11+W11 -> 4 | Z11: 18000 | AA11: Pcs | AB11: =Y11 -> 4 | AC11: 2 | AE11: =AD11+AC11 -> 2 | AG11: Pcs | AH11: =AE11 -> 2 | AI11: 0 | AJ11: 10 | AK11: =AJ11+AI11 -> 10
A12: 7 | B12: Double Tip Ukuran Sedang | C12: Pcs | D12: 10 | E12: 3 | F12: 10 | G12: 13 | H12: 55000 | I12: Pcs | J12: 13 | K12: 6 | M12: =L12+K12 -> 6 | O12: Pcs | P12: 6 | Q12: 5 | S12: =R12+Q12 -> 5 | U12: Pcs | V12: =S12 -> 5 | W12: 5 | Y12: =X12+W12 -> 5 | AA12: Pcs | AB12: =Y12 -> 5 | AC12: 5 | AE12: =AD12+AC12 -> 5 | AG12: Pcs | AH12: =AE12 -> 5 | AI12: 5 | AJ12: 5 | AK12: =AJ12+AI12 -> 10
A13: 8 | B13: Double Tim 3M | C13: Pcs | D13: 5 | E13: 0 | F13: 3 | G13: 3 | H13: 60000 | I13: Pcs | J13: 3 | K13: 0 | L13: 3 | M13: =L13+K13 -> 3 | N13: 165000 | O13: Pcs | P13: 3 | Q13: 2 | S13: =R13+Q13 -> 2 | U13: Pcs | V13: =S13 -> 2 | W13: 2 | Y13: =X13+W13 -> 2 | AA13: Pcs | AB13: =Y13 -> 2 | AC13: 2 | AE13: =AD13+AC13 -> 2 | AG13: Pcs | AH13: =AE13 -> 2 | AI13: 2 | AJ13: 10 | AK13: =AJ13+AI13 -> 12
A14: 9 | B14: Label T & J No. 99 1 pack isi 10 pcs | C14: Pcs | D14: 30 | E14: 20 | G14: 20 | I14: Pcs | J14: 20 | K14: 20 | M14: =L14+K14 -> 20 | O14: Pcs | P14: 20 | Q14: 20 | S14: =R14+Q14 -> 20 | U14: Pcs | V14: =S14 -> 20 | W14: 20 | Y14: =X14+W14 -> 20 | AA14: Pcs | AB14: =Y14 -> 20 | AC14: 20 | AE14: =AD14+AC14 -> 20 | AG14: Pcs | AH14: =AE14 -> 20 | AI14: 20 | AJ14: 10 | AK14: =AJ14+AI14 -> 30
A15: 10 | B15: Label T & J No. 103 1 pack isi 10 pcs | C15: Pcs | D15: 30 | E15: 20 | G15: 20 | I15: Pcs | J15: 20 | K15: 20 | M15: =L15+K15 -> 20 | O15: Pcs | P15: 20 | Q15: 20 | S15: =R15+Q15 -> 20 | U15: Pcs | V15: =S15 -> 20 | W15: 20 | Y15: =X15+W15 -> 20 | AA15: Pcs | AB15: =Y15 -> 20 | AC15: 20 | AE15: =AD15+AC15 -> 20 | AG15: Pcs | AH15: =AE15 -> 20 | AI15: 20 | AJ15: 10 | AK15: =AJ15+AI15 -> 30
A16: 11 | B16: Label T & J No. 104 1 pack isi 10 pcs | C16: Pcs | D16: 10 | E16: 6 | G16: 6 | I16: Pcs | J16: 6 | K16: 2 | L16: 5 | M16: =L16+K16 -> 7 | N16: 27000 | O16: Pcs | P16: 7 | Q16: 7 | S16: =R16+Q16 -> 7 | U16: Pcs | V16: =S16 -> 7 | W16: 6 | Y16: =X16+W16 -> 6 | AA16: Pcs | AB16: =Y16 -> 6 | AC16: 6 | AE16: =AD16+AC16 -> 6 | AG16: Pcs | AH16: =AE16 -> 6 | AI16: 60 | AK16: =AJ16+AI16 -> 60
A17: 12 | B17: Label T & J No. 109 1 pack isi 10 pcs | C17: Pcs | D17: 10 | E17: 10 | G17: 10 | I17: Pcs | J17: 10 | K17: 8 | M17: =L17+K17 -> 8 | O17: Pcs | P17: 8 | Q17: 8 | S17: =R17+Q17 -> 8 | U17: Pcs | V17: =S17 -> 8 | W17: 6 | Y17: =X17+W17 -> 6 | AA17: Pcs | AB17: =Y17 -> 6 | AC17: 6 | AE17: =AD17+AC17 -> 6 | AG17: Pcs | AH17: =AE17 -> 6 | AI17: 10 | AJ17: 20 | AK17: =AJ17+AI17 -> 30
A18: 13 | B18: Label T & J No. 112 1 pack isi 10 pcs | C18: Pcs | D18: 30 | E18: 30 | G18: 30 | I18: Pcs | J18: 30 | K18: 30 | M18: =L18+K18 -> 30 | O18: Pcs | P18: 30 | Q18: 30 | S18: =R18+Q18 -> 30 | U18: Pcs | V18: =S18 -> 30 | W18: 30 | Y18: =X18+W18 -> 30 | AA18: Pcs | AB18: =Y18 -> 30 | AC18: 30 | AE18: =AD18+AC18 -> 30 | AG18: Pcs | AH18: =AE18 -> 30 | AI18: 30 | AK18: =AJ18+AI18 -> 30
A19: 14 | B19: Label T & J No. 121 1 pack isi 10 pcs | C19: Pcs | D19: 33 | E19: 30 | G19: 30 | I19: Pcs | J19: 30 | K19: 30 | M19: =L19+K19 -> 30 | O19: Pcs | P19: 30 | Q19: 30 | S19: =R19+Q19 -> 30 | U19: Pcs | V19: =S19 -> 30 | W19: 30 | Y19: =X19+W19 -> 30 | AA19: Pcs | AB19: =Y19 -> 30 | AC19: 30 | AE19: =AD19+AC19 -> 30 | AG19: Pcs | AH19: =AE19 -> 30 | AI19: 30 | AK19: =AJ19+AI19 -> 30
A20: 15 | B20: Label T & J No. 123 1 pack isi 10 pcs | C20: Pcs | D20: 160 | E20: 159 | G20: 159 | I20: Pcs | J20: 159 | K20: 158 | M20: =L20+K20 -> 158 | O20: Pcs | P20: 158 | Q20: 157 | S20: =R20+Q20 -> 157 | U20: Pcs | V20: =S20 -> 157 | W20: 155 | Y20: =X20+W20 -> 155 | AA20: Pcs | AB20: =Y20 -> 155 | AC20: 153 | AE20: =AD20+AC20 -> 153 | AG20: Pcs | AH20: =AE20 -> 153 | AI20: 150 | AK20: =AJ20+AI20 -> 150
A21: 16 | B21: Label T & J No. 124 1 pack isi 10 pcs | C21: Pcs | D21: 10 | E21: 5 | G21: 5 | I21: Pcs | J21: 5 | K21: 2 | L21: 5 | M21: =L21+K21 -> 7 | N21: 27000 | O21: Pcs | P21: 7 | Q21: 6 | S21: =R21+Q21 -> 6 | U21: Pcs | V21: =S21 -> 6 | W21: 6 | Y21: =X21+W21 -> 6 | AA21: Pcs | AB21: =Y21 -> 6 | AC21: 6 | AE21: =AD21+AC21 -> 6 | AG21: Pcs | AH21: =AE21 -> 6 | AI21: 40 | AK21: =AJ21+AI21 -> 40
A22: 17 | B22: Label T & J No. 126 1 pack isi 10 pcs | C22: Pcs | D22: 20 | E22: 20 | G22: 20 | I22: Pcs | J22: 20 | K22: 20 | M22: =L22+K22 -> 20 | O22: Pcs | P22: 20 | Q22: 20 | S22: =R22+Q22 -> 20 | U22: Pcs | V22: =S22 -> 20 | W22: 20 | Y22: =X22+W22 -> 20 | AA22: Pcs | AB22: =Y22 -> 20 | AC22: 20 | AE22: =AD22+AC22 -> 20 | AG22: Pcs | AH22: =AE22 -> 20 | AI22: 20 | AJ22: 20 | AK22: =AJ22+AI22 -> 40
A23: 18 | B23: Baterai Alkalin 1.5V A2 Isi 6 | C23: Pcs | D23: 14 | E23: 8 | G23: 8 | I23: Pcs | J23: 8 | K23: 4 | L23: 72 | M23: =L23+K23 -> 76 | N23: 336000 | O23: Pcs | P23: 76 | Q23: 38 | S23: =R23+Q23 -> 38 | U23: Pcs | V23: =S23 -> 38 | W23: 8 | X23: 42 | Y23: =X23+W23 -> 50 | Z23: 245000 | AA23: Pcs | AB23: =Y23 -> 50 | AC23: 2 | AD23: 60 | AE23: =AD23+AC23 -> 62 | AF23: 400000 | AG23: Pcs | AH23: =AE23 -> 62 | AI23: 42 | AK23: =AJ23+AI23 -> 42 | AM23: 6
A24: 19 | B24: Baterai Alkalin 1.5V A3 Isi 6 | C24: Pcs | D24: 14 | E24: 3 | F24: 6 | G24: 9 | H24: 28000 | I24: Pcs | J24: 9 | K24: 2 | L24: 72 | M24: =L24+K24 -> 74 | N24: 336000 | O24: Pcs | P24: 74 | Q24: 47 | S24: =R24+Q24 -> 47 | U24: Pcs | V24: =S24 -> 47 | W24: 7 | X24: 42 | Y24: =X24+W24 -> 49 | Z24: 245000 | AA24: Pcs | AB24: =Y24 -> 49 | AC24: 23 | AE24: =AD24+AC24 -> 23 | AG24: Pcs | AH24: =AE24 -> 23 | AI24: 6 | AK24: =AJ24+AI24 -> 6 | AM24: 3
A25: 20 | B25: Ballpoint Pilot Ball Liner Medium Black 1 pack isi 12 pcs | C25: Pcs | D25: 36 | E25: 25 | G25: 25 | I25: Pcs | J25: 25 | K25: 18 | L25: 40 | M25: =L25+K25 -> 58 | N25: 168000 | O25: Pcs | P25: 58 | Q25: 42 | S25: =R25+Q25 -> 42 | U25: Pcs | V25: =S25 -> 42 | W25: 23 | Y25: =X25+W25 -> 23 | AA25: Pcs | AB25: =Y25 -> 23 | AC25: 17 | AE25: =AD25+AC25 -> 17 | AG25: Pcs | AH25: =AE25 -> 17 | AI25: 17 | AJ25: 12 | AK25: =AJ25+AI25 -> 29
A26: 21 | B26: Ballpoint Pilot Ball Liner Medium Blue 1 pack isi 12 pcs | C26: Pcs | D26: 48 | E26: 40 | G26: 40 | I26: Pcs | J26: 40 | K26: 10 | L26: 46 | M26: =L26+K26 -> 56 | N26: 504000 | O26: Pcs | P26: 56 | Q26: 40 | S26: =R26+Q26 -> 40 | U26: Pcs | V26: =S26 -> 40 | W26: 31 | Y26: =X26+W26 -> 31 | AA26: Pcs | AB26: =Y26 -> 31 | AC26: 25 | AE26: =AD26+AC26 -> 25 | AG26: Pcs | AH26: =AE26 -> 25 | AI26: 25 | AK26: =AJ26+AI26 -> 25
A27: 22 | B27: Ballpoint Zebra Sarasa Clip Black (1.0) 1 pack isi 12 pcs | C27: Pcs | D27: 8 | E27: 6 | G27: 6 | I27: Pcs | J27: 6 | K27: 3 | M27: =L27+K27 -> 3 | O27: Pcs | P27: 3 | Q27: 1 | R27: 12 | S27: =R27+Q27 -> 13 | T27: 187200 | U27: Pcs | V27: =S27 -> 13 | W27: 9 | Y27: =X27+W27 -> 9 | AA27: Pcs | AB27: =Y27 -> 9 | AC27: 5 | AE27: =AD27+AC27 -> 5 | AG27: Pcs | AH27: =AE27 -> 5 | AI27: 0 | AK27: =AJ27+AI27 -> 0
A28: 23 | B28: Ballpoint Zebra Sarasa Clip Black (0,7) 1 pack isi 12 pcs | C28: Pcs | D28: 8 | E28: 5 | G28: 5 | I28: Pcs | J28: 5 | K28: 3 | M28: =L28+K28 -> 3 | O28: Pcs | P28: 3 | Q28: 1 | S28: =R28+Q28 -> 1 | U28: Pcs | V28: =S28 -> 1 | W28: 0 | Y28: =X28+W28 -> 0 | AA28: Pcs | AB28: =Y28 -> 0 | AC28: 0 | AE28: =AD28+AC28 -> 0 | AG28: Pcs | AH28: =AE28 -> 0 | AI28: 0 | AK28: =AJ28+AI28 -> 0
A29: 24 | B29: Ballpoint Zebra Sarasa Clip Black (0.5) 1 pack isi 12 pcs | C29: Pcs | D29: 29 | E29: 5 | F29: 24 | G29: 29 | H29: 324000 | I29: Pcs | J29: 29 | K29: 21 | M29: =L29+K29 -> 21 | O29: Pcs | P29: 21 | Q29: 4 | R29: 60 | S29: =R29+Q29 -> 64 | T29: 810000 | U29: Pcs | V29: =S29 -> 64 | W29: 30 | Y29: =X29+W29 -> 30 | AA29: Pcs | AB29: =Y29 -> 30 | AC29: 15 | AE29: =AD29+AC29 -> 15 | AG29: Pcs | AH29: =AE29 -> 15 | AI29: 5 | AK29: =AJ29+AI29 -> 5
A30: 25 | B30: Pulpen Snowman V5 0.7 Merah | C30: Pcs | D30: 6 | E30: 3 | F30: 5 | G30: 8 | H30: 13000 | I30: Pcs | J30: 8 | K30: 5 | M30: =L30+K30 -> 5 | O30: Pcs | P30: 5 | Q30: 5 | S30: =R30+Q30 -> 5 | U30: Pcs | V30: =S30 -> 5 | W30: 5 | Y30: =X30+W30 -> 5 | AA30: Pcs | AB30: =Y30 -> 5 | AC30: 5 | AE30: =AD30+AC30 -> 5 | AG30: Pcs | AH30: =AE30 -> 5 | AI30: 5 | AK30: =AJ30+AI30 -> 5
A31: 26 | B31: Clear Holder Folio F4 Size Isi 60 | C31: Pcs | D31: 33 | E31: 28 | G31: 28 | I31: Pcs | J31: 28 | K31: 25 | M31: =L31+K31 -> 25 | O31: Pcs | P31: 25 | Q31: 24 | S31: =R31+Q31 -> 24 | U31: Pcs | V31: =S31 -> 24 | W31: 24 | Y31: =X31+W31 -> 24 | AA31: Pcs | AB31: =Y31 -> 24 | AC31: 24 | AE31: =AD31+AC31 -> 24 | AG31: Pcs | AH31: =AE31 -> 24 | AI31: 24 | AJ31: 60 | AK31: =AJ31+AI31 -> 84
A32: 27 | B32: Benex Black 2 Rings (75mm) Labela | C32: Pcs | D32: 35 | E32: 33 | G32: 33 | I32: Pcs | J32: 33 | K32: 30 | M32: =L32+K32 -> 30 | O32: Pcs | P32: 30 | Q32: 29 | S32: =R32+Q32 -> 29 | U32: Pcs | V32: =S32 -> 29 | W32: 26 | Y32: =X32+W32 -> 26 | AA32: Pcs | AB32: =Y32 -> 26 | AC32: 24 | AE32: =AD32+AC32 -> 24 | AG32: Pcs | AH32: =AE32 -> 24 | AI32: 24 | AK32: =AJ32+AI32 -> 24
A33: 28 | B33: Sign Here Warna Warni Joyko 1 pack isi 12 pcs | C33: Pcs | D33: 1 | E33: 0 | F33: 12 | G33: 12 | H33: 192000 | I33: Pcs | J33: 12 | K33: 8 | M33: =L33+K33 -> 8 | O33: Pcs | P33: 8 | Q33: 8 | S33: =R33+Q33 -> 8 | U33: Pcs | V33: =S33 -> 8 | W33: 8 | Y33: =X33+W33 -> 8 | AA33: Pcs | AB33: =Y33 -> 8 | AC33: 8 | AE33: =AD33+AC33 -> 8 | AG33: Pcs | AH33: =AE33 -> 8 | AI33: 8 | AK33: =AJ33+AI33 -> 8
A34: 29 | B34: Sign Here Biasa Joyko 1 pack isi 24 pcs | C34: Pcs | D34: 204 | E34: 200 | G34: 200 | I34: Pcs | J34: 200 | K34: 178 | M34: 178 | O34: Pcs | P34: 178 | Q34: 166 | S34: =R34+Q34 -> 166 | U34: Pcs | V34: =S34 -> 166 | W34: 150 | Y34: =X34+W34 -> 150 | AA34: Pcs | AB34: =Y34 -> 150 | AC34: 148 | AE34: =AD34+AC34 -> 148 | AG34: Pcs | AH34: =AE34 -> 148 | AI34: 144 | AJ34: 2 | AK34: =AJ34+AI34 -> 146
A35: 30 | B35: Sticky Notes Kecil (5x5 cm) Pronto 1 pack isi 12 pcs | C35: Pack | D35: 13 | E35: 13 | G35: 12 | I35: Pcs | J35: 13 | K35: 13 | M35: =L35+K35 -> 13 | O35: Pack | P35: 13 | Q35: 13 | S35: =R35+Q35 -> 13 | U35: Pack | V35: =S35 -> 13 | W35: 13 | Y35: =X35+W35 -> 13 | AA35: Pack | AB35: =Y35 -> 13 | AC35: 13 | AE35: =AD35+AC35 -> 13 | AG35: Pack | AH35: =AE35 -> 13 | AI35: 13 | AK35: =AJ35+AI35 -> 13
A36: 31 | B36: Sticky Notes Sedang 76 x 51 mm Pronto 1 pack isi 12 pcs | C36: Pcs | D36: 151 | E36: 147 | G36: 147 | I36: Pcs | J36: 147 | K36: 146 | M36: =L36+K36 -> 146 | O36: Pcs | P36: 146 | Q36: 145 | S36: =R36+Q36 -> 145 | U36: Pcs | V36: =S36 -> 145 | W36: 144 | Y36: =X36+W36 -> 144 | AA36: Pcs | AB36: =Y36 -> 144 | AC36: 144 | AE36: =AD36+AC36 -> 144 | AG36: Pcs | AH36: =AE36 -> 144 | AI36: 144 | AK36: =AJ36+AI36 -> 144
A37: 32 | B37: Sticky Notes Besar 76 x 76 mm Pronto 1 pack isi 12 pcs | C37: Pcs | D37: 12 | E37: 10 | G37: 10 | I37: Pcs | J37: 10 | K37: 9 | M37: =L37+K37 -> 9 | O37: Pcs | P37: 8 | Q37: 8 | S37: =R37+Q37 -> 8 | U37: Pcs | V37: =S37 -> 8 | W37: 7 | Y37: =X37+W37 -> 7 | AA37: Pcs | AB37: =Y37 -> 7 | AC37: 7 | AE37: =AD37+AC37 -> 7 | AG37: Pcs | AH37: =AE37 -> 7 | AI37: 7 | AJ37: 24 | AK37: =AJ37+AI37 -> 31
A38: 33 | B38: Kertas A4 (75 gram) | C38: Rim | D38: 6 | E38: 2 | F38: 30 | G38: 32 | H38: 1290000 | I38: Rim | J38: 32 | K38: 3 | L38: 70 | M38: =L38+K38 -> 73 | N38: 2940000 | O38: Rim | P38: 73 | Q38: 64 | S38: =R38+Q38 -> 64 | U38: Rim | V38: =S38 -> 64 | W38: 8 | X38: 50 | Y38: =X38+W38 -> 58 | Z38: 2475000 | AA38: Rim | AB38: =Y38 -> 58 | AD38: 40 | AE38: =AD38+AC38 -> 40 | AF38: 1792000 | AG38: Rim | AH38: =AE38 -> 40 | AI38: 48 | AJ38: 5 | AK38: =AJ38+AI38 -> 53 | AM38: 19 | AN38: =AM38-3 -> 16
A39: 34 | B39: Kertas F4 (75 gram) | C39: Rim | D39: 13 | E39: 11 | G39: 11 | I39: Rim | J39: 11 | K39: 11 | M39: =L39+K39 -> 11 | O39: Rim | P39: 11 | Q39: 11 | S39: =R39+Q39 -> 11 | U39: Rim | V39: =S39 -> 11 | W39: 11 | Y39: =X39+W39 -> 11 | AA39: Rim | AB39: =Y39 -> 11 | AC39: 11 | AE39: =AD39+AC39 -> 11 | AG39: Rim | AH39: =AE39 -> 11 | AI39: 11 | AK39: =AJ39+AI39 -> 11
A40: 35 | B40: Kertas Kop BPJS Kesehatan | C40: Rim | D40: 11 | E40: 9 | G40: 9 | I40: Rim | J40: 9 | K40: 5 | M40: =L40+K40 -> 5 | O40: Rim | P40: 5 | Q40: 2 | S40: 2 | U40: Rim | V40: =S40 -> 2 | W40: 1 | X40: 10 | Y40: =X40+W40 -> 11 | AA40: Rim | AB40: =Y40 -> 11 | AC40: 8 | AE40: =AD40+AC40 -> 8 | AG40: Rim | AH40: =AE40 -> 8 | AI40: 3 | AK40: =AJ40+AI40 -> 3
A41: 36 | B41: Bindex File Jumbo 1034B | C41: Pcs | D41: 24 | E41: 20 | G41: 20 | I41: Pcs | J41: 20 | K41: 14 | M41: =L41+K41 -> 14 | O41: Pcs | P41: 14 | Q41: 13 | S41: =R41+Q41 -> 13 | U41: Pcs | V41: =S41 -> 13 | W41: 13 | Y41: =X41+W41 -> 13 | AA41: Pcs | AB41: =Y41 -> 13 | AC41: 11 | AE41: =AD41+AC41 -> 11 | AG41: Pcs | AH41: =AE41 -> 11 | AI41: 10 | AK41: =AJ41+AI41 -> 10
...
